<?xml version="1.0" ?>
<!-- =================================================================================== -->
<!-- |    This document was autogenerated by xacro from /home/mili/marvin/ros2_ws/src/marvin/urdf/marvin.urdf.xacro | -->
<!-- |    EDITING THIS FILE BY HAND IS NOT RECOMMENDED                                 | -->
<!-- =================================================================================== -->
<robot name="simple_two_armed_robot">
  <!-- Define a 'world' link as an anchor point (invisible and non-collidable) -->
  <link name="world"/>
  <!-- Connect 'world' link to 'base_link' with a fixed joint to position the robot above ground -->
  <joint name="world_to_base" type="fixed">
    <parent link="world"/>
    <child link="base_link"/>
    <!-- Adjust Z in the origin to set the height above ground -->
    <origin rpy="0 0 0" xyz="0 0 0.5"/>
  </joint>
  <!-- Material Definitions -->
  <material name="blue">
    <color rgba="0 0 1 1"/>
  </material>
  <material name="green">
    <color rgba="0 1 0 1"/>
  </material>
  <material name="red">
    <color rgba="1 0 0 1"/>
  </material>
  <!-- base_link (Torso) Link -->
  <link name="base_link">
    <inertial>
      <origin rpy="0 0 0" xyz="0 0 0"/>
      <mass value="10.0"/>
      <inertia ixx="0.1" ixy="0" ixz="0" iyy="0.1" iyz="0" izz="0.2"/>
    </inertial>
    <visual>
      <geometry>
        <box size="0.5 0.5 1"/>
      </geometry>
      <material name="blue"/>
    </visual>
  </link>
  <link name="left_arm">
    <inertial>
      <origin rpy="0 0 0" xyz="0 0 0"/>
      <mass value="1.0"/>
      <inertia ixx="0.01" ixy="0" ixz="0" iyy="0.01" iyz="0" izz="0.02"/>
    </inertial>
    <visual>
      <geometry>
        <cylinder length="1" radius="0.1"/>
      </geometry>
      <origin rpy="0 0 0" xyz="0.1 0 -0.5"/>
      <material name="green"/>
    </visual>
  </link>
  <link name="right_arm">
    <inertial>
      <origin rpy="0 0 0" xyz="0 0 0"/>
      <mass value="1.0"/>
      <inertia ixx="0.01" ixy="0" ixz="0" iyy="0.01" iyz="0" izz="0.02"/>
    </inertial>
    <visual>
      <geometry>
        <cylinder length="1" radius="0.1"/>
      </geometry>
      <origin rpy="0 0 0" xyz="-0.1 0 -0.5"/>
      <material name="red"/>
    </visual>
  </link>
  <joint name="left_shoulder" type="revolute">
    <parent link="base_link"/>
    <child link="left_arm"/>
    <origin rpy="0 0 0" xyz="0.25 0 0.5"/>
    <axis xyz="0 1 0"/>
    <limit effort="100" lower="-1.5" upper="1.5" velocity="0.5"/>
  </joint>
  <joint name="right_shoulder" type="revolute">
    <parent link="base_link"/>
    <child link="right_arm"/>
    <origin rpy="0 0 0" xyz="-0.25 0 0.5"/>
    <axis xyz="0 1 0"/>
    <limit effort="100" lower="-1.5" upper="1.5" velocity="0.5"/>
  </joint>
</robot>
