<?xml version="1.0"?>
<robot xmlns:xacro="http://www.ros.org/wiki/xacro" name="simple_two_armed_robot">

  <!-- Macro Definitions -->
  <xacro:macro name="cylinder_link" params="name length radius origin color">
    <link name="${name}">
      <visual>
        <geometry>
          <cylinder length="${length}" radius="${radius}"/>
        </geometry>
        <origin xyz="${origin}" rpy="0 0 0"/>
        <material name="${color}"/>
      </visual>
    </link>
  </xacro:macro>

  <xacro:macro name="revolute_joint" params="name parent child origin axis lower_limit upper_limit">
    <joint name="${name}" type="revolute">
      <parent link="${parent}"/>
      <child link="${child}"/>
      <origin xyz="${origin}" rpy="0 0 0"/>
      <axis xyz="${axis}"/>
      <limit lower="${lower_limit}" upper="${upper_limit}" effort="100" velocity="0.5"/>
    </joint>
  </xacro:macro>

  <!-- Material Definitions -->
  <material name="blue">
    <color rgba="0 0 1 1"/>
  </material>

  <material name="green">
    <color rgba="0 1 0 1"/>
  </material>

  <material name="red">
    <color rgba="1 0 0 1"/>
  </material>

  <!-- base_link (Torso) Link -->
  <link name="base_link">
    <visual>
      <geometry>
        <box size="0.5 0.5 1"/>
      </geometry>
      <material name="blue"/>
    </visual>
  </link>

  <!-- Left and Right Arm Links -->
  <xacro:cylinder_link name="left_arm" length="1" radius="0.1" origin="0.1 0 -0.5" color="green"/>
  <xacro:cylinder_link name="right_arm" length="1" radius="0.1" origin="-0.1 0 -0.5" color="red"/>

  <!-- Left and Right Shoulder Joints -->
  <xacro:revolute_joint name="left_shoulder" parent="base_link" child="left_arm" origin="0.25 0 0.5" axis="0 1 0" lower_limit="-1.5" upper_limit="1.5"/>
  <xacro:revolute_joint name="right_shoulder" parent="base_link" child="right_arm" origin="-0.25 0 0.5" axis="0 1 0" lower_limit="-1.5" upper_limit="1.5"/>

</robot>