<?xml version="1.0" ?>
<!-- =================================================================================== -->
<!-- |    This document was autogenerated by xacro from marvin.xacro                   | -->
<!-- |    EDITING THIS FILE BY HAND IS NOT RECOMMENDED                                 | -->
<!-- =================================================================================== -->
<robot name="simple_two_armed_robot">
  <!-- Material Definitions -->
  <material name="blue">
    <color rgba="0 0 1 1"/>
  </material>
  <material name="green">
    <color rgba="0 1 0 1"/>
  </material>
  <material name="red">
    <color rgba="1 0 0 1"/>
  </material>
  <!-- Body (Torso) Link -->
  <link name="body">
    <visual>
      <geometry>
        <box size="0.5 0.5 1"/>
      </geometry>
      <material name="blue"/>
    </visual>
  </link>
  <link name="left_arm">
    <visual>
      <geometry>
        <cylinder length="1" radius="0.1"/>
      </geometry>
      <material name="green"/>
    </visual>
  </link>
  <link name="right_arm">
    <visual>
      <geometry>
        <cylinder length="1" radius="0.1"/>
      </geometry>
      <material name="red"/>
    </visual>
  </link>
  <joint name="left_shoulder" type="revolute">
    <parent link="body"/>
    <child link="left_arm"/>
    <origin rpy="0 0 0" xyz="0.25 0 -0.5"/>
    <axis xyz="1 0 0"/>
    <limit effort="100" lower="-" upper="1" velocity="0.5"/>
  </joint>
  <joint name="right_shoulder" type="revolute">
    <parent link="body"/>
    <child link="right_arm"/>
    <origin rpy="0 0 0" xyz="-0.25 0 -0.5"/>
    <axis xyz="1 0 0"/>
    <limit effort="100" lower="-" upper="1" velocity="0.5"/>
  </joint>
</robot>
